Workbook

Sheet Instrucciones
A1: ANOVA DE LA CALIBRACIÓN DEL ALGORITMO GENÉTICO, PASO A PASO
A3: Hoja "Corridas": los 135 resultados del diseño factorial 3³ (5 réplicas por combinación).
A4: Cada fila es una corrida del AG con su población, probabilidad de cruce, probabilidad de mutación y semilla.
A5: La respuesta analizada es la tardanza total ΣTj (columna E).
A7: Hoja "ANOVA": todas las cifras se calculan con fórmulas a partir de "Corridas". Pueden revisar cada celda.
A8: 1. Media general de ΣTj.
A9: 2. Efectos principales: media de cada nivel; SC del factor = Σ n_nivel · (media_nivel − media general)².
A10: 3. Interacciones dobles: SC = Σ n_celda · (media_celda − media_nivel_A − media_nivel_B + media general)².
A11: 4. SC total = Σ (ΣTj − media general)² (función DESVIA2 / DEVSQ).
A12: 5. SC del error = SC total − suma de las SC de los efectos (incluye la interacción triple).
A13: 6. CM = SC / gl; F = CM / CM del error; valor p = DISTR.F (cola derecha).
A15: Resultado esperado: población (F ≈ 20,65) y mutación (F ≈ 8,65) significativas (p < 0,001);
... A19: Para comprobar que los datos son reproducibles, usen fase2/verificar_reproduccion.py.

Sheet Corridas
A1: Población | B1: Prob. cruce | C1: Prob. mutación | D1: Semilla | E1: ΣTj (h) | F1: Cmax (h)
A2: 50 | B2: 0.7 | C2: 0.1 | D2: 1001 | E2: 99.962 | F2: 771.962
A3: 50 | B3: 0.7 | C3: 0.1 | D3: 1002 | E3: 4.2413333 | F3: 676.1715
A4: 50 | B4: 0.7 | C4: 0.1 | D4: 1003 | E4: 46.914 | F4: 718.914
A5: 50 | B5: 0.7 | C5: 0.1 | D5: 1004 | E5: 74.190167 | F5: 746.19017
A6: 50 | B6: 0.7 | C6: 0.1 | D6: 1005 | E6: 83.819833 | F6: 755.81983
A7: 50 | B7: 0.7 | C7: 0.3 | D7: 1001 | E7: 51.125667 | F7: 723.12567
A8: 50 | B8: 0.7 | C8: 0.3 | D8: 1002 | E8: 8.6473333 | F8: 680.64733
A9: 50 | B9: 0.7 | C9: 0.3 | D9: 1003 | E9: 46.965833 | F9: 718.96583
A10: 50 | B10: 0.7 | C10: 0.3 | D10: 1004 | E10: 56.531333 | F10: 728.53133
A11: 50 | B11: 0.7 | C11: 0.3 | D11: 1005 | E11: 4.7016667 | F11: 676.70167
A12: 50 | B12: 0.7 | C12: 0.5 | D12: 1001 | E12: 42.746167 | F12: 714.74617
A13: 50 | B13: 0.7 | C13: 0.5 | D13: 1002 | E13: 1.7428333 | F13: 673.74283
... A136: 150 | B136: 0.9 | C136: 0.5 | D136: 1005 | E136: 0 | F136: 660.92033

Sheet ANOVA
A1: ANOVA de la tardanza total (ΣTj)
A3: Media general | B3: =AVERAGE(Corridas!$E$2:$E$136)
A4: Número de corridas | B4: =COUNT(Corridas!$E$2:$E$136)
A6: Efecto principal: Población
A7: Nivel | B7: n | C7: Media ΣTj | D7: n·(media − media general)²
A8: 50 | B8: =COUNTIF(Corridas!$A$2:$A$136,A8) | C8: =AVERAGEIF(Corridas!$A$2:$A$136,A8,Corridas!$E$2:$E$136) | D8: =B8*(C8-$B$3)^2
A9: 100 | B9: =COUNTIF(Corridas!$A$2:$A$136,A9) | C9: =AVERAGEIF(Corridas!$A$2:$A$136,A9,Corridas!$E$2:$E$136) | D9: =B9*(C9-$B$3)^2
A10: 150 | B10: =COUNTIF(Corridas!$A$2:$A$136,A10) | C10: =AVERAGEIF(Corridas!$A$2:$A$136,A10,Corridas!$E$2:$E$136) | D10: =B10*(C10-$B$3)^2
C11: SC | D11: =SUM(D8:D10)
A13: Efecto principal: Prob. cruce
A14: Nivel | B14: n | C14: Media ΣTj | D14: n·(media − media general)²
A15: 0.7 | B15: =COUNTIF(Corridas!$B$2:$B$136,A15) | C15: =AVERAGEIF(Corridas!$B$2:$B$136,A15,Corridas!$E$2:$E$136) | D15: =B15*(C15-$B$3)^2
A16: 0.8 | B16: =COUNTIF(Corridas!$B$2:$B$136,A16) | C16: =AVERAGEIF(Corridas!$B$2:$B$136,A16,Corridas!$E$2:$E$136) | D16: =B16*(C16-$B$3)^2
A17: 0.9 | B17: =COUNTIF(Corridas!$B$2:$B$136,A17) | C17: =AVERAGEIF(Corridas!$B$2:$B$136,A17,Corridas!$E$2:$E$136) | D17: =B17*(C17-$B$3)^2
C18: SC | D18: =SUM(D15:D17)
A20: Efecto principal: Prob. mutación
A21: Nivel | B21: n | C21: Media ΣTj | D21: n·(media − media general)²
A22: 0.1 | B22: =COUNTIF(Corridas!$C$2:$C$136,A22) | C22: =AVERAGEIF(Corridas!$C$2:$C$136,A22,Corridas!$E$2:$E$136) | D22: =B22*(C22-$B$3)^2
A23: 0.3 | B23: =COUNTIF(Corridas!$C$2:$C$136,A23) | C23: =AVERAGEIF(Corridas!$C$2:$C$136,A23,Corridas!$E$2:$E$136) | D23: =B23*(C23-$B$3)^2
A24: 0.5 | B24: =COUNTIF(Corridas!$C$2:$C$136,A24) | C24: =AVERAGEIF(Corridas!$C$2:$C$136,A24,Corridas!$E$2:$E$136) | D24: =B24*(C24-$B$3)^2
C25: SC | D25: =SUM(D22:D24)
A27: Interacción: Población × Prob. cruce
A28: Población | B28: Prob. cruce | C28: n | D28: Media celda | E28: n·(celda − A − B + general)²
A29: 50 | B29: 0.7 | C29: =COUNTIFS(Corridas!$A$2:$A$136,A29,Corridas!$B$2:$B$136,B29) | D29: =AVERAGEIFS(Corridas!$E$2:$E$136,Corridas!$A$2:$A$136,A29,Corridas!$B$2:$B$136,B29) | E29: =C29*(D29-$C$8-$C$15+$B$3)^2
A30: 50 | B30: 0.8 | C30: =COUNTIFS(Corridas!$A$2:$A$136,A30,Corridas!$B$2:$B$136,B30) | D30: =AVERAGEIFS(Corridas!$E$2:$E$136,Corridas!$A$2:$A$136,A30,Corridas!$B$2:$B$136,B30) | E30: =C30*(D30-$C$8-$C$16+$B$3)^2
A31: 50 | B31: 0.9 | C31: =COUNTIFS(Corridas!$A$2:$A$136,A31,Corridas!$B$2:$B$136,B31) | D31: =AVERAGEIFS(Corridas!$E$2:$E$136,Corridas!$A$2:$A$136,A31,Corridas!$B$2:$B$136,B31) | E31: =C31*(D31-$C$8-$C$17+$B$3)^2
A32: 100 | B32: 0.7 | C32: =COUNTIFS(Corridas!$A$2:$A$136,A32,Corridas!$B$2:$B$136,B32) | D32: =AVERAGEIFS(Corridas!$E$2:$E$136,Corridas!$A$2:$A$136,A32,Corridas!$B$2:$B$136,B32) | E32: =C32*(D32-$C$9-$C$15+$B$3)^2
A33: 100 | B33: 0.8 | C33: =COUNTIFS(Corridas!$A$2:$A$136,A33,Corridas!$B$2:$B$136,B33) | D33: =AVERAGEIFS(Corridas!$E$2:$E$136,Corridas!$A$2:$A$136,A33,Corridas!$B$2:$B$136,B33) | E33: =C33*(D33-$C$9-$C$16+$B$3)^2
A34: 100 | B34: 0.9 | C34: =COUNTIFS(Corridas!$A$2:$A$136,A34,Corridas!$B$2:$B$136,B34) | D34: =AVERAGEIFS(Corridas!$E$2:$E$136,Corridas!$A$2:$A$136,A34,Corridas!$B$2:$B$136,B34) | E34: =C34*(D34-$C$9-$C$17+$B$3)^2
A35: 150 | B35: 0.7 | C35: =COUNTIFS(Corridas!$A$2:$A$136,A35,Corridas!$B$2:$B$136,B35) | D35: =AVERAGEIFS(Corridas!$E$2:$E$136,Corridas!$A$2:$A$136,A35,Corridas!$B$2:$B$136,B35) | E35: =C35*(D35-$C$10-$C$15+$B$3)^2
A36: 150 | B36: 0.8 | C36: =COUNTIFS(Corridas!$A$2:$A$136,A36,Corridas!$B$2:$B$136,B36) | D36: =AVERAGEIFS(Corridas!$E$2:$E$136,Corridas!$A$2:$A$136,A36,Corridas!$B$2:$B$136,B36) | E36: =C36*(D36-$C$10-$C$16+$B$3)^2
A37: 150 | B37: 0.9 | C37: =COUNTIFS(Corridas!$A$2:$A$136,A37,Corridas!$B$2:$B$136,B37) | D37: =AVERAGEIFS(Corridas!$E$2:$E$136,Corridas!$A$2:$A$136,A37,Corridas!$B$2:$B$136,B37) | E37: =C37*(D37-$C$10-$C$17+$B$3)^2
D38: SC | E38: =SUM(E29:E37)
A40: Interacción: Población × Prob. mutación
A41: Población | B41: Prob. mutación | C41: n | D41: Media celda | E41: n·(celda − A − B + general)²
A42: 50 | B42: 0.1 | C42: =COUNTIFS(Corridas!$A$2:$A$136,A42,Corridas!$C$2:$C$136,B42) | D42: =AVERAGEIFS(Corridas!$E$2:$E$136,Corridas!$A$2:$A$136,A42,Corridas!$C$2:$C$136,B42) | E42: =C42*(D42-$C$8-$C$22+$B$3)^2
A43: 50 | B43: 0.3 | C43: =COUNTIFS(Corridas!$A$2:$A$136,A43,Corridas!$C$2:$C$136,B43) | D43: =AVERAGEIFS(Corridas!$E$2:$E$136,Corridas!$A$2:$A$136,A43,Corridas!$C$2:$C$136,B43) | E43: =C43*(D43-$C$8-$C$23+$B$3)^2
A44: 50 | B44: 0.5 | C44: =COUNTIFS(Corridas!$A$2:$A$136,A44,Corridas!$C$2:$C$136,B44) | D44: =AVERAGEIFS(Corridas!$E$2:$E$136,Corridas!$A$2:$A$136,A44,Corridas!$C$2:$C$136,B44) | E44: =C44*(D44-$C$8-$C$24+$B$3)^2
A45: 100 | B45: 0.1 | C45: =COUNTIFS(Corridas!$A$2:$A$136,A45,Corridas!$C$2:$C$136,B45) | D45: =AVERAGEIFS(Corridas!$E$2:$E$136,Corridas!$A$2:$A$136,A45,Corridas!$C$2:$C$136,B45) | E45: =C45*(D45-$C$9-$C$22+$B$3)^2
A46: 100 | B46: 0.3 | C46: =COUNTIFS(Corridas!$A$2:$A$136,A46,Corridas!$C$2:$C$136,B46) | D46: =AVERAGEIFS(Corridas!$E$2:$E$136,Corridas!$A$2:$A$136,A46,Corridas!$C$2:$C$136,B46) | E46: =C46*(D46-$C$9-$C$23+$B$3)^2
...
